Workbook

Sheet Sheet1 (2)
A1: nomor | B1: baris | C1: PBT | D1: NIB | E1: Keadaan Tanah | F1: Tanda Batas | G1: Penunjuk Batas | H1: Hal lain-lain | I1: Nama Jalan | J1: Nomor Jalan | K1: Alamat Tambahan | L1: Kode Pos | M1: Penggunaan | N1: Pemanfaatan | O1: Metode Ukur | P1: Akurasi Bidang | Q1: CEK
A2: 1 | B2: 2 | C2: 138 | D2: 00013 | E2: =IFERROR(IF(OR(VLOOKUP(D2,'Sheet1 (3)'!$C:$F,4,FALSE)="RMH",VLOOKUP(D2,'Sheet1 (3)'!$C:$F,4,FALSE)="PKR",VLOOKUP(D2,'Sheet1 (3)'!$C:$F,4,FALSE)=""),"Non Pertanian","Pertanian"),"Non Pertanian") -> Pertanian | F2: patok Beton | G2: =IFERROR("Sesuai dengan petunjuk pemilik tanah : "&VLOOKUP(D2,'Sheet1 (3)'!$C:$D,2,FALSE),"") -> Sesuai dengan petunjuk pemilik tanah : Tamrin | H2: sesuai gambar ukur 07/SEKUDUK/2026 | I2: - | J2: - | K2: - | L2: - | M2: Perdesaan | N2: =IFERROR(IF(VLOOKUP(D2,'Sheet1 (3)'!$C:$F,4,FALSE)="","Tanah Perkampungan",CHOOSE(MATCH(VLOOKUP(D2,'Sheet1 (3)'!$C:$F,4,FALSE),{"PKR","RMH","SWH","KBN"},0),"Tanah Perkampungan","Permukiman","Tanah Persawahan","Tanah Kebun")),"Tanah Pekarangan") -> Tanah Kebun | O2: =IF(IFERROR(VLOOKUP(D2,'Sheet1 (3)'!$C:$G,5,FALSE),"")="K1","Pengukuran Terestris yang pemetaannya diikatkan ke peta foto","Identifikasi batas bidang tanah diatas peta foto/citra") -> Identifikasi batas bidang tanah diatas peta foto/citra | P2: 0.4
A3: 2 | B3: 3 | C3: 138 | D3: 00014 | E3: =IFERROR(IF(OR(VLOOKUP(D3,'Sheet1 (3)'!$C:$F,4,FALSE)="RMH",VLOOKUP(D3,'Sheet1 (3)'!$C:$F,4,FALSE)="PKR",VLOOKUP(D3,'Sheet1 (3)'!$C:$F,4,FALSE)=""),"Non Pertanian","Pertanian"),"Non Pertanian") -> Pertanian | F3: patok Beton | G3: =IFERROR("Sesuai dengan petunjuk pemilik tanah : "&VLOOKUP(D3,'Sheet1 (3)'!$C:$D,2,FALSE),"") -> Sesuai dengan petunjuk pemilik tanah : Samsul | H3: sesuai gambar ukur 07/SEKUDUK/2026 | I3: - | J3: - | K3: - | L3: - | M3: Perdesaan | N3: =IFERROR(IF(VLOOKUP(D3,'Sheet1 (3)'!$C:$F,4,FALSE)="","Tanah Perkampungan",CHOOSE(MATCH(VLOOKUP(D3,'Sheet1 (3)'!$C:$F,4,FALSE),{"PKR","RMH","SWH","KBN"},0),"Tanah Perkampungan","Permukiman","Tanah Persawahan","Tanah Kebun")),"Tanah Pekarangan") -> Tanah Kebun | O3: =IF(IFERROR(VLOOKUP(D3,'Sheet1 (3)'!$C:$G,5,FALSE),"")="K1","Pengukuran Terestris yang pemetaannya diikatkan ke peta foto","Identifikasi batas bidang tanah diatas peta foto/citra") -> Identifikasi batas bidang tanah diatas peta foto/citra | P3: 0.4
A4: 3 | B4: 4 | C4: 138 | D4: 00015 | E4: =IFERROR(IF(OR(VLOOKUP(D4,'Sheet1 (3)'!$C:$F,4,FALSE)="RMH",VLOOKUP(D4,'Sheet1 (3)'!$C:$F,4,FALSE)="PKR",VLOOKUP(D4,'Sheet1 (3)'!$C:$F,4,FALSE)=""),"Non Pertanian","Pertanian"),"Non Pertanian") -> Pertanian | F4: patok Beton | G4: =IFERROR("Sesuai dengan petunjuk pemilik tanah : "&VLOOKUP(D4,'Sheet1 (3)'!$C:$D,2,FALSE),"") -> Sesuai dengan petunjuk pemilik tanah : Marpuah | H4: sesuai gambar ukur 07/SEKUDUK/2026 | I4: - | J4: - | K4: - | L4: - | M4: Perdesaan | N4: =IFERROR(IF(VLOOKUP(D4,'Sheet1 (3)'!$C:$F,4,FALSE)="","Tanah Perkampungan",CHOOSE(MATCH(VLOOKUP(D4,'Sheet1 (3)'!$C:$F,4,FALSE),{"PKR","RMH","SWH","KBN"},0),"Tanah Perkampungan","Permukiman","Tanah Persawahan","Tanah Kebun")),"Tanah Pekarangan") -> Tanah Kebun | O4: =IF(IFERROR(VLOOKUP(D4,'Sheet1 (3)'!$C:$G,5,FALSE),"")="K1","Pengukuran Terestris yang pemetaannya diikatkan ke peta foto","Identifikasi batas bidang tanah diatas peta foto/citra") -> Identifikasi batas bidang tanah diatas peta foto/citra | P4: 0.4
A5: 4 | B5: 5 | C5: 138 | D5: 00016 | E5: =IFERROR(IF(OR(VLOOKUP(D5,'Sheet1 (3)'!$C:$F,4,FALSE)="RMH",VLOOKUP(D5,'Sheet1 (3)'!$C:$F,4,FALSE)="PKR",VLOOKUP(D5,'Sheet1 (3)'!$C:$F,4,FALSE)=""),"Non Pertanian","Pertanian"),"Non Pertanian") -> Pertanian | F5: patok Beton | G5: =IFERROR("Sesuai dengan petunjuk pemilik tanah : "&VLOOKUP(D5,'Sheet1 (3)'!$C:$D,2,FALSE),"") -> Sesuai dengan petunjuk pemilik tanah : Mutamam Alm | H5: sesuai gambar ukur 07/SEKUDUK/2026 | I5: - | J5: - | K5: - | L5: - | M5: Perdesaan | N5: =IFERROR(IF(VLOOKUP(D5,'Sheet1 (3)'!$C:$F,4,FALSE)="","Tanah Perkampungan",CHOOSE(MATCH(VLOOKUP(D5,'Sheet1 (3)'!$C:$F,4,FALSE),{"PKR","RMH","SWH","KBN"},0),"Tanah Perkampungan","Permukiman","Tanah Persawahan","Tanah Kebun")),"Tanah Pekarangan") -> Tanah Kebun | O5: =IF(IFERROR(VLOOKUP(D5,'Sheet1 (3)'!$C:$G,5,FALSE),"")="K1","Pengukuran Terestris yang pemetaannya diikatkan ke peta foto","Identifikasi batas bidang tanah diatas peta foto/citra") -> Identifikasi batas bidang tanah diatas peta foto/citra | P5: 0.4
A6: 5 | B6: 6 | C6: 138 | D6: 00017 | E6: =IFERROR(IF(OR(VLOOKUP(D6,'Sheet1 (3)'!$C:$F,4,FALSE)="RMH",VLOOKUP(D6,'Sheet1 (3)'!$C:$F,4,FALSE)="PKR",VLOOKUP(D6,'Sheet1 (3)'!$C:$F,4,FALSE)=""),"Non Pertanian","Pertanian"),"Non Pertanian") -> Pertanian | F6: patok Beton | G6: =IFERROR("Sesuai dengan petunjuk pemilik tanah : "&VLOOKUP(D6,'Sheet1 (3)'!$C:$D,2,FALSE),"") -> Sesuai dengan petunjuk pemilik tanah : Sabiran | H6: sesuai gambar ukur 07/SEKUDUK/2026 | I6: - | J6: - | K6: - | L6: - | M6: Perdesaan | N6: =IFERROR(IF(VLOOKUP(D6,'Sheet1 (3)'!$C:$F,4,FALSE)="","Tanah Perkampungan",CHOOSE(MATCH(VLOOKUP(D6,'Sheet1 (3)'!$C:$F,4,FALSE),{"PKR","RMH","SWH","KBN"},0),"Tanah Perkampungan","Permukiman","Tanah Persawahan","Tanah Kebun")),"Tanah Pekarangan") -> Tanah Kebun | O6: =IF(IFERROR(VLOOKUP(D6,'Sheet1 (3)'!$C:$G,5,FALSE),"")="K1","Pengukuran Terestris yang pemetaannya diikatkan ke peta foto","Identifikasi batas bidang tanah diatas peta foto/citra") -> Identifikasi batas bidang tanah diatas peta foto/citra | P6: 0.4
A7: 6 | B7: 7 | C7: 138 | D7: 00018 | E7: =IFERROR(IF(OR(VLOOKUP(D7,'Sheet1 (3)'!$C:$F,4,FALSE)="RMH",VLOOKUP(D7,'Sheet1 (3)'!$C:$F,4,FALSE)="PKR",VLOOKUP(D7,'Sheet1 (3)'!$C:$F,4,FALSE)=""),"Non Pertanian","Pertanian"),"Non Pertanian") -> Pertanian | F7: patok Beton | G7: =IFERROR("Sesuai dengan petunjuk pemilik tanah : "&VLOOKUP(D7,'Sheet1 (3)'!$C:$D,2,FALSE),"") -> Sesuai dengan petunjuk pemilik tanah : Wafida | H7: sesuai gambar ukur 07/SEKUDUK/2026 | I7: - | J7: - | K7: - | L7: - | M7: Perdesaan | N7: =IFERROR(IF(VLOOKUP(D7,'Sheet1 (3)'!$C:$F,4,FALSE)="","Tanah Perkampungan",CHOOSE(MATCH(VLOOKUP(D7,'Sheet1 (3)'!$C:$F,4,FALSE),{"PKR","RMH","SWH","KBN"},0),"Tanah Perkampungan","Permukiman","Tanah Persawahan","Tanah Kebun")),"Tanah Pekarangan") -> Tanah Kebun | O7: =IF(IFERROR(VLOOKUP(D7,'Sheet1 (3)'!$C:$G,5,FALSE),"")="K1","Pengukuran Terestris yang pemetaannya diikatkan ke peta foto","Identifikasi batas bidang tanah diatas peta foto/citra") -> Identifikasi batas bidang tanah diatas peta foto/citra | P7: 0.4
A8: 7 | B8: 8 | C8: 138 | D8: 00019 | E8: =IFERROR(IF(OR(VLOOKUP(D8,'Sheet1 (3)'!$C:$F,4,FALSE)="RMH",VLOOKUP(D8,'Sheet1 (3)'!$C:$F,4,FALSE)="PKR",VLOOKUP(D8,'Sheet1 (3)'!$C:$F,4,FALSE)=""),"Non Pertanian","Pertanian"),"Non Pertanian") -> Pertanian | F8: patok Beton | G8: =IFERROR("Sesuai dengan petunjuk pemilik tanah : "&VLOOKUP(D8,'Sheet1 (3)'!$C:$D,2,FALSE),"") -> Sesuai dengan petunjuk pemilik tanah : Azizah | H8: sesuai gambar ukur 07/SEKUDUK/2026 | I8: - | J8: - | K8: - | L8: - | M8: Perdesaan | N8: =IFERROR(IF(VLOOKUP(D8,'Sheet1 (3)'!$C:$F,4,FALSE)="","Tanah Perkampungan",CHOOSE(MATCH(VLOOKUP(D8,'Sheet1 (3)'!$C:$F,4,FALSE),{"PKR","RMH","SWH","KBN"},0),"Tanah Perkampungan","Permukiman","Tanah Persawahan","Tanah Kebun")),"Tanah Pekarangan") -> Tanah Kebun | O8: =IF(IFERROR(VLOOKUP(D8,'Sheet1 (3)'!$C:$G,5,FALSE),"")="K1","Pengukuran Terestris yang pemetaannya diikatkan ke peta foto","Identifikasi batas bidang tanah diatas peta foto/citra") -> Identifikasi batas bidang tanah diatas peta foto/citra | P8: 0.4
A9: 8 | B9: 9 | C9: 138 | D9: 00020 | E9: =IFERROR(IF(OR(VLOOKUP(D9,'Sheet1 (3)'!$C:$F,4,FALSE)="RMH",VLOOKUP(D9,'Sheet1 (3)'!$C:$F,4,FALSE)="PKR",VLOOKUP(D9,'Sheet1 (3)'!$C:$F,4,FALSE)=""),"Non Pertanian","Pertanian"),"Non Pertanian") -> Pertanian | F9: patok Beton | G9: =IFERROR("Sesuai dengan petunjuk pemilik tanah : "&VLOOKUP(D9,'Sheet1 (3)'!$C:$D,2,FALSE),"") -> Sesuai dengan petunjuk pemilik tanah : Mutamam Alm | H9: sesuai gambar ukur 07/SEKUDUK/2026 | I9: - | J9: - | K9: - | L9: - | M9: Perdesaan | N9: =IFERROR(IF(VLOOKUP(D9,'Sheet1 (3)'!$C:$F,4,FALSE)="","Tanah Perkampungan",CHOOSE(MATCH(VLOOKUP(D9,'Sheet1 (3)'!$C:$F,4,FALSE),{"PKR","RMH","SWH","KBN"},0),"Tanah Perkampungan","Permukiman","Tanah Persawahan","Tanah Kebun")),"Tanah Pekarangan") -> Tanah Kebun | O9: =IF(IFERROR(VLOOKUP(D9,'Sheet1 (3)'!$C:$G,5,FALSE),"")="K1","Pengukuran Terestris yang pemetaannya diikatkan ke peta foto","Identifikasi batas bidang tanah diatas peta foto/citra") -> Identifikasi batas bidang tanah diatas peta foto/citra | P9: 0.4
A10: 9 | B10: 10 | C10: 138 | D10: 00021 | E10: =IFERROR(IF(OR(VLOOKUP(D10,'Sheet1 (3)'!$C:$F,4,FALSE)="RMH",VLOOKUP(D10,'Sheet1 (3)'!$C:$F,4,FALSE)="PKR",VLOOKUP(D10,'Sheet1 (3)'!$C:$F,4,FALSE)=""),"Non Pertanian","Pertanian"),"Non Pertanian") -> Pertanian | F10: patok Beton | G10: =IFERROR("Sesuai dengan petunjuk pemilik tanah : "&VLOOKUP(D10,'Sheet1 (3)'!$C:$D,2,FALSE),"") -> Sesuai dengan petunjuk pemilik tanah : Tarmuzi | H10: sesuai gambar ukur 07/SEKUDUK/2026 | I10: - | J10: - | K10: - | L10: - | M10: Perdesaan | N10: =IFERROR(IF(VLOOKUP(D10,'Sheet1 (3)'!$C:$F,4,FALSE)="","Tanah Perkampungan",CHOOSE(MATCH(VLOOKUP(D10,'Sheet1 (3)'!$C:$F,4,FALSE),{"PKR","RMH","SWH","KBN"},0),"Tanah Perkampungan","Permukiman","Tanah Persawahan","Tanah Kebun")),"Tanah Pekarangan") -> Tanah Kebun | O10: =IF(IFERROR(VLOOKUP(D10,'Sheet1 (3)'!$C:$G,5,FALSE),"")="K1","Pengukuran Terestris yang pemetaannya diikatkan ke peta foto","Identifikasi batas bidang tanah diatas peta foto/citra") -> Identifikasi batas bidang tanah diatas peta foto/citra | P10: 0.4
A11: 10 | B11: 11 | C11: 138 | D11: 00022 | E11: =IFERROR(IF(OR(VLOOKUP(D11,'Sheet1 (3)'!$C:$F,4,FALSE)="RMH",VLOOKUP(D11,'Sheet1 (3)'!$C:$F,4,FALSE)="PKR",VLOOKUP(D11,'Sheet1 (3)'!$C:$F,4,FALSE)=""),"Non Pertanian","Pertanian"),"Non Pertanian") -> Pertanian | F11: patok Beton | G11: =IFERROR("Sesuai dengan petunjuk pemilik tanah : "&VLOOKUP(D11,'Sheet1 (3)'!$C:$D,2,FALSE),"") -> Sesuai dengan petunjuk pemilik tanah : Rusminin | H11: sesuai gambar ukur 07/SEKUDUK/2026 | I11: - | J11: - | K11: - | L11: - | M11: Perdesaan | N11: =IFERROR(IF(VLOOKUP(D11,'Sheet1 (3)'!$C:$F,4,FALSE)="","Tanah Perkampungan",CHOOSE(MATCH(VLOOKUP(D11,'Sheet1 (3)'!$C:$F,4,FALSE),{"PKR","RMH","SWH","KBN"},0),"Tanah Perkampungan","Permukiman","Tanah Persawahan","Tanah Kebun")),"Tanah Pekarangan") -> Tanah Kebun | O11: =IF(IFERROR(VLOOKUP(D11,'Sheet1 (3)'!$C:$G,5,FALSE),"")="K1","Pengukuran Terestris yang pemetaannya diikatkan ke peta foto","Identifikasi batas bidang tanah diatas peta foto/citra") -> Identifikasi batas bidang tanah diatas peta foto/citra | P11: 0.4
A12: 11 | B12: 12 | C12: 138 | D12: 00023 | E12: =IFERROR(IF(OR(VLOOKUP(D12,'Sheet1 (3)'!$C:$F,4,FALSE)="RMH",VLOOKUP(D12,'Sheet1 (3)'!$C:$F,4,FALSE)="PKR",VLOOKUP(D12,'Sheet1 (3)'!$C:$F,4,FALSE)=""),"Non Pertanian","Pertanian"),"Non Pertanian") -> Pertanian | F12: patok Beton | G12: =IFERROR("Sesuai dengan petunjuk pemilik tanah : "&VLOOKUP(D12,'Sheet1 (3)'!$C:$D,2,FALSE),"") -> Sesuai dengan petunjuk pemilik tanah : Wafida | H12: sesuai gambar ukur 07/SEKUDUK/2026 | I12: - | J12: - | K12: - | L12: - | M12: Perdesaan | N12: =IFERROR(IF(VLOOKUP(D12,'Sheet1 (3)'!$C:$F,4,FALSE)="","Tanah Perkampungan",CHOOSE(MATCH(VLOOKUP(D12,'Sheet1 (3)'!$C:$F,4,FALSE),{"PKR","RMH","SWH","KBN"},0),"Tanah Perkampungan","Permukiman","Tanah Persawahan","Tanah Kebun")),"Tanah Pekarangan") -> Tanah Kebun | O12: =IF(IFERROR(VLOOKUP(D12,'Sheet1 (3)'!$C:$G,5,FALSE),"")="K1","Pengukuran Terestris yang pemetaannya diikatkan ke peta foto","Identifikasi batas bidang tanah diatas peta foto/citra") -> Pengukuran Terestris yang pemetaannya diikatkan ke peta foto | P12: 0.4
A13: 12 | B13: 13 | C13: 138 | D13: 00024 | E13: =IFERROR(IF(OR(VLOOKUP(D13,'Sheet1 (3)'!$C:$F,4,FALSE)="RMH",VLOOKUP(D13,'Sheet1 (3)'!$C:$F,4,FALSE)="PKR",VLOOKUP(D13,'Sheet1 (3)'!$C:$F,4,FALSE)=""),"Non Pertanian","Pertanian"),"Non Pertanian") -> Pertanian | F13: patok Beton | G13: =IFERROR("Sesuai dengan petunjuk pemilik tanah : "&VLOOKUP(D13,'Sheet1 (3)'!$C:$D,2,FALSE),"") -> Sesuai dengan petunjuk pemilik tanah : Musfalah | H13: sesuai gambar ukur 07/SEKUDUK/2026 | I13: - | J13: - | K13: - | L13: - | M13: Perdesaan | N13: =IFERROR(IF(VLOOKUP(D13,'Sheet1 (3)'!$C:$F,4,FALSE)="","Tanah Perkampungan",CHOOSE(MATCH(VLOOKUP(D13,'Sheet1 (3)'!$C:$F,4,FALSE),{"PKR","RMH","SWH","KBN"},0),"Tanah Perkampungan","Permukiman","Tanah Persawahan","Tanah Kebun")),"Tanah Pekarangan") -> Tanah Kebun | O13: =IF(IFERROR(VLOOKUP(D13,'Sheet1 (3)'!$C:$G,5,FALSE),"")="K1","Pengukuran Terestris yang pemetaannya diikatkan ke peta foto","Identifikasi batas bidang tanah diatas peta foto/citra") -> Pengukuran Terestris yang pemetaannya diikatkan ke peta foto | P13: 0.4
... A169: 168 | B169: 169 | C169: 138 | D169: 00180 | E169: =IFERROR(IF(OR(VLOOKUP(D169,'Sheet1 (3)'!$C:$F,4,FALSE)="RMH",VLOOKUP(D169,'Sheet1 (3)'!$C:$F,4,FALSE)="PKR",VLOOKUP(D169,'Sheet1 (3)'!$C:$F,4,FALSE)=""),"Non Pertanian","Pertanian"),"Non Pertanian") -> Non Pertanian | F169: patok Beton | G169: =IFERROR("Sesuai dengan petunjuk pemilik tanah : "&VLOOKUP(D169,'Sheet1 (3)'!$C:$D,2,FALSE),"") -> Sesuai dengan petunjuk pemilik tanah : Jalan | H169: sesuai gambar ukur 07/SEKUDUK/2026 | I169: - | J169: - | K169: - | L169: - | M169: Perdesaan | N169: =IFERROR(IF(VLOOKUP(D169,'Sheet1 (3)'!$C:$F,4,FALSE)="","Tanah Perkampungan",CHOOSE(MATCH(VLOOKUP(D169,'Sheet1 (3)'!$C:$F,4,FALSE),{"PKR","RMH","SWH","KBN"},0),"Tanah Perkampungan","Permukiman","Tanah Persawahan","Tanah Kebun")),"Tanah Pekarangan") -> Tanah Perkampungan | O169: =IF(IFERROR(VLOOKUP(D169,'Sheet1 (3)'!$C:$G,5,FALSE),"")="K1","Pengukuran Terestris yang pemetaannya diikatkan ke peta foto","Identifikasi batas bidang tanah diatas peta foto/citra") -> Identifikasi batas bidang tanah diatas peta foto/citra | P169: 0.4

Sheet Sheet1 (3)
A1: NUB | B1: NOP | C1: NIB | D1: NAMA | E1: NIK | F1: KONDISI | G1: NOHAK | H1: LUAS | I1: X | J1: Y | K1: DWGNAME | L1: NoLembar | M1: NoKotak
A2: 774 | C2: 00013 | D2: Tamrin | E2: 6101061807630005 | F2: KBN | G2: K3 | H2: 14735.631 | I2: 175632.01 | J2: 1657782.5 | K2: 7.SEKUDUK 1 168 BIDANG.dwg | L2: 24.230-08.3 | M2: B3
A3: 775 | C3: 00014 | D3: Samsul | E3: 6101061807630005 | F3: KBN | G3: K3 | H3: 2808.636 | I3: 175643.66 | J3: 1657636.2 | K3: 7.SEKUDUK 1 168 BIDANG.dwg | L3: 24.230-08.3 | M3: B2
A4: 776 | C4: 00015 | D4: Marpuah | E4: 6101064207530003 | F4: KBN | G4: K3 | H4: 16774.374 | I4: 175706.82 | J4: 1657769.5 | K4: 7.SEKUDUK 1 168 BIDANG.dwg | L4: 24.230-08.3 | M4: C3
A5: 777 | C5: 00016 | D5: Mutamam Alm | E5: 6101060306600004 | F5: KBN | G5: K3 | H5: 5963.756 | I5: 175711.48 | J5: 1657959.1 | K5: 7.SEKUDUK 1 168 BIDANG.dwg | L5: 24.230-08.3 | M5: C5
A6: 778 | C6: 00017 | D6: Sabiran | E6: 6101061801690002 | F6: KBN | G6: K3 | H6: 6305.239 | I6: 175749.98 | J6: 1657952 | K6: 7.SEKUDUK 1 168 BIDANG.dwg | L6: 24.230-08.3 | M6: C5
A7: 779 | C7: 00018 | D7: Wafida | E7: 6101061807630005 | F7: KBN | G7: K3 | H7: 17411.955 | I7: 175756.08 | J7: 1657711.4 | K7: 7.SEKUDUK 1 168 BIDANG.dwg | L7: 24.230-08.3 | M7: C3
A8: 780 | C8: 00019 | D8: Azizah | E8: 6101065012850001 | F8: KBN | G8: K3 | H8: 5789.745 | I8: 175787.07 | J8: 1657945.9 | K8: 7.SEKUDUK 1 168 BIDANG.dwg | L8: 24.230-08.3 | M8: C5
A9: 781 | C9: 00020 | D9: Mutamam Alm | E9: 6101060306600004 | F9: KBN | G9: K3 | H9: 5625.848 | I9: 175809.63 | J9: 1657922.2 | K9: 7.SEKUDUK 1 168 BIDANG.dwg | L9: 24.230-08.3 | M9: D5
A10: 782 | C10: 00021 | D10: Tarmuzi | E10: 6101062809850001 | F10: KBN | G10: K3 | H10: 9900.409 | I10: 175816.58 | J10: 1657706 | K10: 7.SEKUDUK 1 168 BIDANG.dwg | L10: 24.230-08.3 | M10: D3
A11: 783 | C11: 00022 | D11: Rusminin | E11: 6101060301710002 | F11: KBN | G11: K3 | H11: 7695.763 | I11: 175842.05 | J11: 1657918.6 | K11: 7.SEKUDUK 1 168 BIDANG.dwg | L11: 24.230-08.3 | M11: D5
A12: 784 | C12: 00023 | D12: Wafida | E12: 6101066307670001 | F12: KBN | G12: K1 | H12: 17234.72 | I12: 175850.14 | J12: 1657627.1 | K12: 7.SEKUDUK 1 168 BIDANG.dwg | L12: 24.230-08.3 | M12: D2
A13: 785 | C13: 00024 | D13: Musfalah | E13: 6101064103750003 | F13: KBN | G13: K1 | H13: 8642.368 | I13: 175859.82 | J13: 1657704.1 | K13: 7.SEKUDUK 1 168 BIDANG.dwg | L13: 24.230-08.3 | M13: D3
... A59: 831 | C59: 00070 | D59: Hajali | E59: 6101061502880003 | F59: KBN | G59: K3 | H59: 2390.038 | I59: 176243.77 | J59: 1657195.2 | K59: 7.SEKUDUK 1 168 BIDANG.dwg | L59: 25.230-01.7 | M59: C2
A60: 832 | C60: 00071 | D60: Jalan | E60: 6101061807630005 | H60: 4159.353 | I60: 176244.75 | J60: 1657970 | K60: 7.SEKUDUK 1 168 BIDANG.dwg | L60: 25.230-05.1 | M60: C5
A61: 833 | C61: 00072 | D61: Saluran Air | E61: 6101061807630005 | H61: 5075.172 | I61: 176244.81 | J61: 1657975.2 | K61: 7.SEKUDUK 1 168 BIDANG.dwg | L61: 25.230-05.1 | M61: C5
A62: 834 | C62: 00073 | D62: Hasman | E62: 6101061807630005 | F62: KBN | G62: K3 | H62: 1202.814 | I62: 176245.51 | J62: 1657010.6 | K62: 7.SEKUDUK 1 168 BIDANG.dwg | L62: 25.230-01.7 | M62: C1
A63: 835 | C63: 00074 | D63: Ikhwan | E63: 6101060909730002 | F63: KBN | G63: K1 | H63: 4101.28 | I63: 176245.68 | J63: 1657357.6 | K63: 7.SEKUDUK 1 168 BIDANG.dwg | L63: 25.230-01.7 | M63: C4
A64: 836 | C64: 00075 | D64: Sapar | E64: 6101061807630005 | F64: KBN | G64: K3 | H64: 6273.857 | I64: 176256.48 | J64: 1657079.5 | K64: 7.SEKUDUK 1 168 BIDANG.dwg | L64: 25.230-01.7 | M64: C1
A65: 837 | C65: 00076 | D65: Wal'ah | E65: 6101066003690001 | F65: KBN | G65: K3 | H65: 3771.257 | I65: 176268.41 | J65: 1657668.3 | K65: 7.SEKUDUK 1 168 BIDANG.dwg | L65: 25.230-05.1 | M65: C2
A66: 838 | C66: 00077 | D66: Erlian | E66: 6101060608650003 | F66: KBN | G66: K3 | H66: 1800.489 | I66: 176276.23 | J66: 1657091.5 | K66: 7.SEKUDUK 1 168 BIDANG.dwg | L66: 25.230-01.7 | M66: C1
A67: 839 | C67: 00078 | D67: Nuraliah | E67: 6101065807810004 | F67: KBN | G67: K3 | H67: 10385.355 | I67: 176279.93 | J67: 1657813.3 | K67: 7.SEKUDUK 1 168 BIDANG.dwg | L67: 25.230-05.1 | M67: C4
A68: 840 | C68: 00079 | D68: Herlian | E68: 6101061807630005 | F68: KBN | G68: K3 | H68: 10596.664 | I68: 176294.9 | J68: 1657872.1 | K68: 7.SEKUDUK 1 168 BIDANG.dwg | L68: 25.230-05.1 | M68: C4
A69: 841 | C69: 00080 | D69: Rahmi Anggraini | E69: 6101066803100001 | F69: KBN | G69: K3 | H69: 6042.582 | I69: 176294.99 | J69: 1657678.9 | K69: 7.SEKUDUK 1 168 BIDANG.dwg | L69: 25.230-05.1 | M69: C2
A70: 842 | C70: 00081 | D70: Ika Zulaika | E70: 6101065910930001 | F70: KBN | G70: K1 | H70: 5324.624 | I70: 176295.91 | J70: 1657401.1 | K70: 7.SEKUDUK 1 168 BIDANG.dwg | L70: 25.230-01.7 | M70: C5
A71: 843 | C71: 00082 | D71: Husin | E71: 6101062205830002 | F71: KBN | G71: K3 | H71: 6410.745 | I71: 176296.45 | J71: 1657524.6 | K71: 7.SEKUDUK 1 168 BIDANG.dwg | L71: 25.230-05.1 | M71: C1
A72: 844 | C72: 00083 | D72: Husban, S.pd.i | E72: 6101062111700003 | F72: KBN | G72: K3 | H72: 4333.875 | I72: 176309.63 | J72: 1657698.2 | K72: 7.SEKUDUK 1 168 BIDANG.dwg | L72: 25.230-05.1 | M72: D2
A73: 845 | C73: 00084 | D73: Husin | E73: 6101062205830002 | F73: KBN | G73: K3 | H73: 13600.801 | I73: 176311.4 | J73: 1657153.9 | K73: 7.SEKUDUK 1 168 BIDANG.dwg | L73: 25.230-01.7 | M73: D2
... A92: 864 | C92: 00103 | D92: Zamhuri Noer, Amd | E92: 6101060202760002 | F92: KBN | G92: K3 | H92: 7967.213 | I92: 176442.44 | J92: 1657361.2 | K92: 7.SEKUDUK 1 168 BIDANG.dwg | L92: 25.230-01.7 | M92: E4
A93: 865 | C93: 00104 | D93: Saluran Air | E93: 6101061807630005 | H93: 3277.756 | I93: 176442.49 | J93: 1657674.5 | K93: 7.SEKUDUK 1 168 BIDANG.dwg | L93: 25.230-05.1 | M93: E2
A94: 866 | C94: 00105 | D94: Dina Uswatun Hasanah | E94: 6101066708970003 | F94: KBN | G94: K1 | H94: 7079.278 | I94: 176446.11 | J94: 1657210.7 | K94: 7.SEKUDUK 1 168 BIDANG.dwg | L94: 25.230-01.7 | M94: E3
A95: 867 | C95: 00106 | D95: Jalan | E95: 6101061807630005 | H95: 8051.555 | I95: 176447.99 | J95: 1657669.9 | K95: 7.SEKUDUK 1 168 BIDANG.dwg | L95: 25.230-05.1 | M95: E2
A96: 868 | C96: 00107 | D96: Saluran Air | E96: 6101061807630005 | H96: 3292.226 | I96: 176456.18 | J96: 1657668.3 | K96: 7.SEKUDUK 1 168 BIDANG.dwg | L96: 25.230-05.1 | M96: E2
A97: 869 | C97: 00108 | D97: Husban, S.pd.i | E97: 6101062111700003 | F97: KBN | G97: K3 | H97: 1687.987 | I97: 176459.08 | J97: 1657601.7 | K97: 7.SEKUDUK 1 168 BIDANG.dwg | L97: 25.230-05.1 | M97: E2
A98: 870 | C98: 00109 | D98: Abdiah | E98: 6101065009450001 | F98: KBN | G98: K3 | H98: 2463.148 | I98: 176479.61 | J98: 1657888 | K98: 7.SEKUDUK 1 168 BIDANG.dwg | L98: 25.230-05.1 | M98: E4
A99: 871 | C99: 00110 | D99: Ita Lestari | E99: 6101064105910002 | F99: KBN | G99: K3 | H99: 2700.493 | I99: 176489.46 | J99: 1657391.6 | K99: 7.SEKUDUK 1 168 BIDANG.dwg | L99: 25.230-01.7 | M99: E4
A100: 872 | C100: 00111 | D100: Hikmah | E100: 6101067112800001 | F100: KBN | G100: K1 | H100: 1995.111 | I100: 176490.3 | J100: 1657818.9 | K100: 7.SEKUDUK 1 168 BIDANG.dwg | L100: 25.230-05.1 | M100: E4
A101: 873 | C101: 00112 | D101: Makmur | E101: 6101062512600002 | F101: KBN | G101: K3 | H101: 10195.923 | I101: 176516.88 | J101: 1657228.9 | K101: 7.SEKUDUK 1 168 BIDANG.dwg | L101: 25.230-01.8 | M101: A3
A102: 874 | C102: 00113 | D102: Ridwan | E102: 6101171705750001 | F102: KBN | G102: K3 | H102: 10490.874 | I102: 176519.57 | J102: 1657413 | K102: 7.SEKUDUK 1 168 BIDANG.dwg | L102: 25.230-01.8 | M102: A5
A103: 875 | C103: 00114 | D103: Aslia | E103: 6101066309850003 | F103: KBN | G103: K1 | H103: 4714.81 | I103: 176521.31 | J103: 1657584.2 | K103: 7.SEKUDUK 1 168 BIDANG.dwg | L103: 25.230-05.2 | M103: A1
...

Sheet Sheet1
A1: NUB | B1: NOP | C1: NIB | D1: NAMA | E1: NIK | F1: KONDISI | G1: NOHAK | H1: LUAS | I1: X | J1: Y | K1: DWGNAME | L1: NoLembar | M1: NoKotak
A2: 774 | C2: 00013 | D2: Tamrin | E2: 6101061807630004 | F2: KBN | G2: K3 | H2: 14735.631 | I2: 175632.01 | J2: 1657782.5 | K2: 7.SEKUDUK 1 168 BIDANG.dwg | L2: 24.230-08.3 | M2: B3
A3: 775 | C3: 00014 | D3: Samsul | E3: 6101061807630004 | F3: KBN | G3: K3 | H3: 2808.636 | I3: 175643.66 | J3: 1657636.2 | K3: 7.SEKUDUK 1 168 BIDANG.dwg | L3: 24.230-08.3 | M3: B2
A4: 776 | C4: 00015 | D4: Marpuah | E4: 6101064207530003 | F4: KBN | G4: K3 | H4: 16774.374 | I4: 175706.82 | J4: 1657769.5 | K4: 7.SEKUDUK 1 168 BIDANG.dwg | L4: 24.230-08.3 | M4: C3
A5: 777 | C5: 00016 | D5: Mutamam Alm | E5: 6101060306600004 | F5: KBN | G5: K3 | H5: 5963.756 | I5: 175711.48 | J5: 1657959.1 | K5: 7.SEKUDUK 1 168 BIDANG.dwg | L5: 24.230-08.3 | M5: C5
A6: 778 | C6: 00017 | D6: Sabiran | E6: 6101061801690002 | F6: KBN | G6: K3 | H6: 6305.239 | I6: 175749.98 | J6: 1657952 | K6: 7.SEKUDUK 1 168 BIDANG.dwg | L6: 24.230-08.3 | M6: C5
A7: 779 | C7: 00018 | D7: Wafida | E7: 6101061807630004 | F7: KBN | G7: K3 | H7: 17411.955 | I7: 175756.08 | J7: 1657711.4 | K7: 7.SEKUDUK 1 168 BIDANG.dwg | L7: 24.230-08.3 | M7: C3
A8: 780 | C8: 00019 | D8: Azizah | E8: 6101065012850001 | F8: KBN | G8: K3 | H8: 5789.745 | I8: 175787.07 | J8: 1657945.9 | K8: 7.SEKUDUK 1 168 BIDANG.dwg | L8: 24.230-08.3 | M8: C5
A9: 781 | C9: 00020 | D9: Mutamam Alm | E9: 6101060306600004 | F9: KBN | G9: K3 | H9: 5625.848 | I9: 175809.63 | J9: 1657922.2 | K9: 7.SEKUDUK 1 168 BIDANG.dwg | L9: 24.230-08.3 | M9: D5
A10: 782 | C10: 00021 | D10: Tarmuzi | E10: 6101062809850001 | F10: KBN | G10: K3 | H10: 9900.409 | I10: 175816.58 | J10: 1657706 | K10: 7.SEKUDUK 1 168 BIDANG.dwg | L10: 24.230-08.3 | M10: D3
A11: 783 | C11: 00022 | D11: Rusminin | E11: 6101060301710002 | F11: KBN | G11: K3 | H11: 7695.763 | I11: 175842.05 | J11: 1657918.6 | K11: 7.SEKUDUK 1 168 BIDANG.dwg | L11: 24.230-08.3 | M11: D5
A12: 784 | C12: 00023 | D12: Wafida | E12: 6101066307670001 | F12: KBN | G12: K1 | H12: 17234.72 | I12: 175850.14 | J12: 1657627.1 | K12: 7.SEKUDUK 1 168 BIDANG.dwg | L12: 24.230-08.3 | M12: D2
A13: 785 | C13: 00024 | D13: Musfalah | E13: 6101064103750003 | F13: KBN | G13: K1 | H13: 8642.368 | I13: 175859.82 | J13: 1657704.1 | K13: 7.SEKUDUK 1 168 BIDANG.dwg | L13: 24.230-08.3 | M13: D3
... A59: 831 | C59: 00070 | D59: Hajali | E59: 6101061502880003 | F59: KBN | G59: K3 | H59: 2390.038 | I59: 176243.77 | J59: 1657195.2 | K59: 7.SEKUDUK 1 168 BIDANG.dwg | L59: 25.230-01.7 | M59: C2
A60: 832 | C60: 00071 | D60: Jalan | E60: 6101061807630005 | H60: 4159.353 | I60: 176244.75 | J60: 1657970 | K60: 7.SEKUDUK 1 168 BIDANG.dwg | L60: 25.230-05.1 | M60: C5
A61: 833 | C61: 00072 | D61: Saluran Air | E61: 6101061807630005 | H61: 5075.172 | I61: 176244.81 | J61: 1657975.2 | K61: 7.SEKUDUK 1 168 BIDANG.dwg | L61: 25.230-05.1 | M61: C5
A62: 834 | C62: 00073 | D62: Hasman | E62: 6101061807630004 | F62: KBN | G62: K3 | H62: 1202.814 | I62: 176245.51 | J62: 1657010.6 | K62: 7.SEKUDUK 1 168 BIDANG.dwg | L62: 25.230-01.7 | M62: C1
A63: 835 | C63: 00074 | D63: Ikhwan | E63: 6101060909730002 | F63: KBN | G63: K1 | H63: 4101.28 | I63: 176245.68 | J63: 1657357.6 | K63: 7.SEKUDUK 1 168 BIDANG.dwg | L63: 25.230-01.7 | M63: C4
A64: 836 | C64: 00075 | D64: Sapar | E64: 6101061807630004 | F64: KBN | G64: K3 | H64: 6273.857 | I64: 176256.48 | J64: 1657079.5 | K64: 7.SEKUDUK 1 168 BIDANG.dwg | L64: 25.230-01.7 | M64: C1
A65: 837 | C65: 00076 | D65: Wal'ah | E65: 6101066003690001 | F65: KBN | G65: K3 | H65: 3771.257 | I65: 176268.41 | J65: 1657668.3 | K65: 7.SEKUDUK 1 168 BIDANG.dwg | L65: 25.230-05.1 | M65: C2
A66: 838 | C66: 00077 | D66: Erlian | E66: 6101060608650003 | F66: KBN | G66: K3 | H66: 1800.489 | I66: 176276.23 | J66: 1657091.5 | K66: 7.SEKUDUK 1 168 BIDANG.dwg | L66: 25.230-01.7 | M66: C1
A67: 839 | C67: 00078 | D67: Nuraliah | E67: 6101065807810004 | F67: KBN | G67: K3 | H67: 10385.355 | I67: 176279.93 | J67: 1657813.3 | K67: 7.SEKUDUK 1 168 BIDANG.dwg | L67: 25.230-05.1 | M67: C4
A68: 840 | C68: 00079 | D68: Herlian | E68: 6101061807630004 | F68: KBN | G68: K3 | H68: 10596.664 | I68: 176294.9 | J68: 1657872.1 | K68: 7.SEKUDUK 1 168 BIDANG.dwg | L68: 25.230-05.1 | M68: C4
A69: 841 | C69: 00080 | D69: Rahmi Anggraini | E69: 6101066803100001 | F69: KBN | G69: K3 | H69: 6042.582 | I69: 176294.99 | J69: 1657678.9 | K69: 7.SEKUDUK 1 168 BIDANG.dwg | L69: 25.230-05.1 | M69: C2
A70: 842 | C70: 00081 | D70: Ika Zulaika | E70: 6101065910930001 | F70: KBN | G70: K1 | H70: 5324.624 | I70: 176295.91 | J70: 1657401.1 | K70: 7.SEKUDUK 1 168 BIDANG.dwg | L70: 25.230-01.7 | M70: C5
A71: 843 | C71: 00082 | D71: Husin | E71: 6101062205830002 | F71: KBN | G71: K3 | H71: 6410.745 | I71: 176296.45 | J71: 1657524.6 | K71: 7.SEKUDUK 1 168 BIDANG.dwg | L71: 25.230-05.1 | M71: C1
A72: 844 | C72: 00083 | D72: Husban, S.pd.i | E72: 6101062111700003 | F72: KBN | G72: K3 | H72: 4333.875 | I72: 176309.63 | J72: 1657698.2 | K72: 7.SEKUDUK 1 168 BIDANG.dwg | L72: 25.230-05.1 | M72: D2
A73: 845 | C73: 00084 | D73: Husin | E73: 6101062205830002 | F73: KBN | G73: K3 | H73: 13600.801 | I73: 176311.4 | J73: 1657153.9 | K73: 7.SEKUDUK 1 168 BIDANG.dwg | L73: 25.230-01.7 | M73: D2
... A92: 864 | C92: 00103 | D92: Zamhuri Noer, Amd | E92: 6101060202760002 | F92: KBN | G92: K3 | H92: 7967.213 | I92: 176442.44 | J92: 1657361.2 | K92: 7.SEKUDUK 1 168 BIDANG.dwg | L92: 25.230-01.7 | M92: E4
A93: 865 | C93: 00104 | D93: Saluran Air | E93: 6101061807630005 | H93: 3277.756 | I93: 176442.49 | J93: 1657674.5 | K93: 7.SEKUDUK 1 168 BIDANG.dwg | L93: 25.230-05.1 | M93: E2
A94: 866 | C94: 00105 | D94: Dina Uswatun Hasanah | E94: 6101066708970003 | F94: KBN | G94: K1 | H94: 7079.278 | I94: 176446.11 | J94: 1657210.7 | K94: 7.SEKUDUK 1 168 BIDANG.dwg | L94: 25.230-01.7 | M94: E3
A95: 867 | C95: 00106 | D95: Jalan | E95: 6101061807630005 | H95: 8051.555 | I95: 176447.99 | J95: 1657669.9 | K95: 7.SEKUDUK 1 168 BIDANG.dwg | L95: 25.230-05.1 | M95: E2
A96: 868 | C96: 00107 | D96: Saluran Air | E96: 6101061807630005 | H96: 3292.226 | I96: 176456.18 | J96: 1657668.3 | K96: 7.SEKUDUK 1 168 BIDANG.dwg | L96: 25.230-05.1 | M96: E2
A97: 869 | C97: 00108 | D97: Husban, S.pd.i | E97: 6101062111700003 | F97: KBN | G97: K3 | H97: 1687.987 | I97: 176459.08 | J97: 1657601.7 | K97: 7.SEKUDUK 1 168 BIDANG.dwg | L97: 25.230-05.1 | M97: E2
A98: 870 | C98: 00109 | D98: Abdiah | E98: 6101065009450001 | F98: KBN | G98: K3 | H98: 2463.148 | I98: 176479.61 | J98: 1657888 | K98: 7.SEKUDUK 1 168 BIDANG.dwg | L98: 25.230-05.1 | M98: E4
A99: 871 | C99: 00110 | D99: Ita Lestari | E99: 6101064105910002 | F99: KBN | G99: K3 | H99: 2700.493 | I99: 176489.46 | J99: 1657391.6 | K99: 7.SEKUDUK 1 168 BIDANG.dwg | L99: 25.230-01.7 | M99: E4
A100: 872 | C100: 00111 | D100: Hikmah | E100: 6101067112800001 | F100: KBN | G100: K1 | H100: 1995.111 | I100: 176490.3 | J100: 1657818.9 | K100: 7.SEKUDUK 1 168 BIDANG.dwg | L100: 25.230-05.1 | M100: E4
A101: 873 | C101: 00112 | D101: Makmur | E101: 6101062512600002 | F101: KBN | G101: K3 | H101: 10195.923 | I101: 176516.88 | J101: 1657228.9 | K101: 7.SEKUDUK 1 168 BIDANG.dwg | L101: 25.230-01.8 | M101: A3
A102: 874 | C102: 00113 | D102: Ridwan | E102: 6101171705750001 | F102: KBN | G102: K3 | H102: 10490.874 | I102: 176519.57 | J102: 1657413 | K102: 7.SEKUDUK 1 168 BIDANG.dwg | L102: 25.230-01.8 | M102: A5
A103: 875 | C103: 00114 | D103: Aslia | E103: 6101066309850003 | F103: KBN | G103: K1 | H103: 4714.81 | I103: 176521.31 | J103: 1657584.2 | K103: 7.SEKUDUK 1 168 BIDANG.dwg | L103: 25.230-05.2 | M103: A1
...
